Workbook
Name Slicer_Gender: #N/A
Name Slicer_Region: #N/A
Name Slicer_Store_Type: #N/A

Sheet Customer_Dim
A1: Customer_ID | B1: Name | C1: Age | D1: Gender | E1: City | F1: State | G1: Country | H1: Loyalty_Level
A2: CUST1000 | B2: sheena bonilla | C2: 55 | D2: Male | E2: Donaldton | F2: North Carolina | G2: USA
A3: CUST1001 | B3: Eugene Nelson | C3: 26 | D3: Female | E3: Phillipsmouth | F3: North Dakota | G3: USA | H3: Platinum
A4: CUST1002 | B4: dr. Benjamin Price | C4: 29 | D4: Female | E4: Kylebury | F4: Alabama | G4: USA | H4: Platinum
A5: CUST1003 | B5: jeremy harris | C5: 59 | D5: Female | E5: Thomastown | F5: Ohio | G5: USA | H5: Bronze
A6: CUST1004 | B6: Caroline Collins | C6: 64 | D6: Female | E6: Nicholasshire | F6: California | G6: USA | H6: Silver
A7: CUST1005 | B7: Christine Vaughn | C7: 24 | D7: Male | E7: East Amandamouth | F7: Oregon | G7: USA | H7: Bronze
A8: CUST1006 | B8: Amber Jackson | C8: 29 | D8: Female | E8: Deborahborough | F8: South Dakota | G8: USA | H8: Platinum
A9: CUST1007 | B9: Daniel Boyd | C9: 29 | D9: Female | E9: West Pamelafurt | F9: West Virginia | G9: USA | H9: Bronze
A10: CUST1008 | B10: Melissa Howard | C10: 53 | D10: Female | E10: Maynardton | F10: New Hampshire | G10: USA | H10: Gold
A11: CUST1009 | B11: Ms. Maria Leach | C11: 64 | D11: Male | E11: Melissashire | F11: Pennsylvania | G11: USA | H11: Platinum
A12: CUST1010 | B12: Dominic Page | C12: 53 | D12: Male | E12: Port Michaelburgh | F12: Pennsylvania | G12: USA | H12: Bronze
A13: CUST1011 | B13: Brian Lopez | C13: 28 | D13: Female | E13: East Krista | F13: New York | G13: USA | H13: Gold
A14: CUST1012 | B14: Kenneth Lambert | C14: 55 | D14: Female | E14: North Kathryn | F14: Kansas | G14: USA | H14: Platinum
... A19: CUST1017 | B19: Adam Cruz | C19: 60 | D19: Female | E19: Brandonville | F19: Georgia | G19: USA | H19: Platinum
A20: CUST1018 | B20: Rhonda Moss | C20: 43 | D20: Male | E20: South William | F20: Kansas | G20: USA
A21: CUST1019 | B21: Michael Torres | C21: 46 | D21: Female | E21: Gonzalezfort | F21: New Jersey | G21: USA | H21: Platinum
A22: CUST1020 | B22: Bridget Allen | C22: 59 | D22: Male | E22: Lake Shaneburgh | F22: Delaware | G22: USA | H22: Silver
A23: CUST1021 | B23: Jeff Martinez | C23: 36 | D23: Female | E23: Smithburgh | F23: Oklahoma | G23: USA | H23: Gold
A24: CUST1022 | B24: paul fox | C24: 33 | D24: Female | E24: Michaelton | F24: Hawaii | G24: USA | H24: Silver
A25: CUST1023 | B25: Jonathan Steele | C25: 52 | D25: Female | E25: Molinabury | F25: Oregon | G25: USA | H25: Silver
A26: CUST1024 | B26: Heather Collins | C26: 40 | D26: Male | E26: Rogerschester | F26: Idaho | G26: USA | H26: Platinum
A27: CUST1025 | B27: Diana Taylor | C27: 59 | D27: Female | E27: Vasqueztown | F27: California | G27: USA | H27: Bronze
A28: CUST1026 | B28: Amber Carlson | C28: 18 | D28: Female | E28: East Michellemouth | F28: Missouri | G28: USA | H28: Gold
A29: CUST1027 | B29: Leslie Johnson | C29: 31 | D29: Male | E29: Mollyshire | F29: Utah | G29: USA
A30: CUST1028 | B30: Joshua Ryan | C30: 27 | D30: Female | E30: New David | F30: New Jersey | G30: USA | H30: Platinum
A31: CUST1029 | B31: David Arnold | C31: 54 | D31: Female | E31: East Jennifer | F31: California | G31: USA | H31: Silver
A32: CUST1030 | B32: Jessica Acevedo | C32: 64 | D32: Female | E32: Amybury | F32: Pennsylvania | G32: USA | H32: Bronze
A33: CUST1031 | B33: Sarah Vance | C33: 41 | D33: Male | E33: Johnsonville | F33: Oregon | G33: USA | H33: Silver
A34: CUST1032 | B34: Mike Jennings | C34: 48 | D34: Female | E34: Fostermouth | F34: Arizona | G34: USA | H34: Gold
A35: CUST1033 | B35: Robert Jones DDS | C35: 25 | D35: Male | E35: Tristanton | F35: Oklahoma | G35: USA | H35: Platinum
A36: CUST1034 | B36: Christopher Olson | C36: 27 | D36: Female | E36: West Richard | F36: Maryland | G36: USA | H36: Platinum
A37: CUST1035 | B37: Rachel Myers | C37: 52 | D37: Male | E37: Robertberg | F37: North Dakota | G37: USA | H37: Silver
A38: CUST1036 | B38: Thomas Phillips | C38: 20 | D38: Female | E38: Luisfurt | F38: Georgia | G38: USA | H38: Gold
A39: CUST1037 | B39: Christopher Carter | C39: 27 | D39: Female | E39: Brendastad | F39: South Dakota | G39: USA
A40: CUST1038 | B40: Deanna Simpson | C40: 35 | D40: Female | E40: Brownport | F40: North Dakota | G40: USA | H40: Bronze
A41: CUST1039 | B41: Tonya Reynolds | C41: 55 | D41: Female | E41: Darleneton | F41: Michigan | G41: USA | H41: Gold
A42: CUST1040 | B42: Eric Vega | C42: 50 | D42: Male | E42: Williamsonland | F42: Kansas | G42: USA | H42: Gold
A43: CUST1041 | B43: James Gibbs | C43: 21 | D43: Male | E43: Mooneyshire | F43: Alaska | G43: USA | H43: Platinum
A44: CUST1042 | B44: William Martin | C44: 19 | D44: Male | E44: Ryanburgh | F44: Connecticut | G44: USA | H44: Platinum
...

Sheet Customer_Dim_Cleaning
A1: Customer_ID | B1: Name | C1: Name2 | D1: Age | E1: Gender | F1: City | G1: City2 | H1: State | I1: Country | J1: Loyalty_Level | K1: Loyalty_Level2
A2: CUST1000 | B2: sheena bonilla | C2: =PROPER(TRIM(B2)) -> Sheena Bonilla | D2: 55 | E2: Male | F2: Donaldton | G2: =PROPER(TRIM(F2)) -> Donaldton | H2: North Carolina | I2: USA | K2: =IF(J2="","Platinum",J2) -> Platinum
A3: CUST1001 | B3: Eugene Nelson | C3: =PROPER(TRIM(B3)) -> Eugene Nelson | D3: 26 | E3: Female | F3: Phillipsmouth | G3: =PROPER(TRIM(F3)) -> Phillipsmouth | H3: North Dakota | I3: USA | J3: Platinum | K3: =IF(J3="","Platinum",J3) -> Platinum
A4: CUST1002 | B4: dr. Benjamin Price | C4: =PROPER(TRIM(B4)) -> Dr. Benjamin Price | D4: 29 | E4: Female | F4: Kylebury | G4: =PROPER(TRIM(F4)) -> Kylebury | H4: Alabama | I4: USA | J4: Platinum | K4: =IF(J4="","Platinum",J4) -> Platinum
A5: CUST1003 | B5: jeremy harris | C5: =PROPER(TRIM(B5)) -> Jeremy Harris | D5: 59 | E5: Female | F5: Thomastown | G5: =PROPER(TRIM(F5)) -> Thomastown | H5: Ohio | I5: USA | J5: Bronze | K5: =IF(J5="","Platinum",J5) -> Bronze
A6: CUST1004 | B6: Caroline Collins | C6: =PROPER(TRIM(B6)) -> Caroline Collins | D6: 64 | E6: Female | F6: Nicholasshire | G6: =PROPER(TRIM(F6)) -> Nicholasshire | H6: California | I6: USA | J6: Silver | K6: =IF(J6="","Platinum",J6) -> Silver
A7: CUST1005 | B7: Christine Vaughn | C7: =PROPER(TRIM(B7)) -> Christine Vaughn | D7: 24 | E7: Male | F7: East Amandamouth | G7: =PROPER(TRIM(F7)) -> East Amandamouth | H7: Oregon | I7: USA | J7: Bronze | K7: =IF(J7="","Platinum",J7) -> Bronze
A8: CUST1006 | B8: Amber Jackson | C8: =PROPER(TRIM(B8)) -> Amber Jackson | D8: 29 | E8: Female | F8: Deborahborough | G8: =PROPER(TRIM(F8)) -> Deborahborough | H8: South Dakota | I8: USA | J8: Platinum | K8: =IF(J8="","Platinum",J8) -> Platinum
A9: CUST1007 | B9: Daniel Boyd | C9: =PROPER(TRIM(B9)) -> Daniel Boyd | D9: 29 | E9: Female | F9: West Pamelafurt | G9: =PROPER(TRIM(F9)) -> West Pamelafurt | H9: West Virginia | I9: USA | J9: Bronze | K9: =IF(J9="","Platinum",J9) -> Bronze
A10: CUST1008 | B10: Melissa Howard | C10: =PROPER(TRIM(B10)) -> Melissa Howard | D10: 53 | E10: Female | F10: Maynardton | G10: =PROPER(TRIM(F10)) -> Maynardton | H10: New Hampshire | I10: USA | J10: Gold | K10: =IF(J10="","Platinum",J10) -> Gold
A11: CUST1009 | B11: Ms. Maria Leach | C11: =PROPER(TRIM(B11)) -> Ms. Maria Leach | D11: 64 | E11: Male | F11: Melissashire | G11: =PROPER(TRIM(F11)) -> Melissashire | H11: Pennsylvania | I11: USA | J11: Platinum | K11: =IF(J11="","Platinum",J11) -> Platinum
A12: CUST1010 | B12: Dominic Page | C12: =PROPER(TRIM(B12)) -> Dominic Page | D12: 53 | E12: Male | F12: Port Michaelburgh | G12: =PROPER(TRIM(F12)) -> Port Michaelburgh | H12: Pennsylvania | I12: USA | J12: Bronze | K12: =IF(J12="","Platinum",J12) -> Bronze
A13: CUST1011 | B13: Brian Lopez | C13: =PROPER(TRIM(B13)) -> Brian Lopez | D13: 28 | E13: Female | F13: East Krista | G13: =PROPER(TRIM(F13)) -> East Krista | H13: New York | I13: USA | J13: Gold | K13: =IF(J13="","Platinum",J13) -> Gold
A14: CUST1012 | B14: Kenneth Lambert | C14: =PROPER(TRIM(B14)) -> Kenneth Lambert | D14: 55 | E14: Female | F14: North Kathryn | G14: =PROPER(TRIM(F14)) -> North Kathryn | H14: Kansas | I14: USA | J14: Platinum | K14: =IF(J14="","Platinum",J14) -> Platinum
... A19: CUST1017 | B19: Adam Cruz | C19: =PROPER(TRIM(B19)) -> Adam Cruz | D19: 60 | E19: Female | F19: Brandonville | G19: =PROPER(TRIM(F19)) -> Brandonville | H19: Georgia | I19: USA | J19: Platinum | K19: =IF(J19="","Platinum",J19) -> Platinum
A20: CUST1018 | B20: Rhonda Moss | C20: =PROPER(TRIM(B20)) -> Rhonda Moss | D20: 43 | E20: Male | F20: South William | G20: =PROPER(TRIM(F20)) -> South William | H20: Kansas | I20: USA | K20: =IF(J20="","Platinum",J20) -> Platinum
A21: CUST1019 | B21: Michael Torres | C21: =PROPER(TRIM(B21)) -> Michael Torres | D21: 46 | E21: Female | F21: Gonzalezfort | G21: =PROPER(TRIM(F21)) -> Gonzalezfort | H21: New Jersey | I21: USA | J21: Platinum | K21: =IF(J21="","Platinum",J21) -> Platinum
A22: CUST1020 | B22: Bridget Allen | C22: =PROPER(TRIM(B22)) -> Bridget Allen | D22: 59 | E22: Male | F22: Lake Shaneburgh | G22: =PROPER(TRIM(F22)) -> Lake Shaneburgh | H22: Delaware | I22: USA | J22: Silver | K22: =IF(J22="","Platinum",J22) -> Silver
A23: CUST1021 | B23: Jeff Martinez | C23: =PROPER(TRIM(B23)) -> Jeff Martinez | D23: 36 | E23: Female | F23: Smithburgh | G23: =PROPER(TRIM(F23)) -> Smithburgh | H23: Oklahoma | I23: USA | J23: Gold | K23: =IF(J23="","Platinum",J23) -> Gold
A24: CUST1022 | B24: paul fox | C24: =PROPER(TRIM(B24)) -> Paul Fox | D24: 33 | E24: Female | F24: Michaelton | G24: =PROPER(TRIM(F24)) -> Michaelton | H24: Hawaii | I24: USA | J24: Silver | K24: =IF(J24="","Platinum",J24) -> Silver
A25: CUST1023 | B25: Jonathan Steele | C25: =PROPER(TRIM(B25)) -> Jonathan Steele | D25: 52 | E25: Female | F25: Molinabury | G25: =PROPER(TRIM(F25)) -> Molinabury | H25: Oregon | I25: USA | J25: Silver | K25: =IF(J25="","Platinum",J25) -> Silver
A26: CUST1024 | B26: Heather Collins | C26: =PROPER(TRIM(B26)) -> Heather Collins | D26: 40 | E26: Male | F26: Rogerschester | G26: =PROPER(TRIM(F26)) -> Rogerschester | H26: Idaho | I26: USA | J26: Platinum | K26: =IF(J26="","Platinum",J26) -> Platinum
A27: CUST1025 | B27: Diana Taylor | C27: =PROPER(TRIM(B27)) -> Diana Taylor | D27: 59 | E27: Female | F27: Vasqueztown | G27: =PROPER(TRIM(F27)) -> Vasqueztown | H27: California | I27: USA | J27: Bronze | K27: =IF(J27="","Platinum",J27) -> Bronze
A28: CUST1026 | B28: Amber Carlson | C28: =PROPER(TRIM(B28)) -> Amber Carlson | D28: 18 | E28: Female | F28: East Michellemouth | G28: =PROPER(TRIM(F28)) -> East Michellemouth | H28: Missouri | I28: USA | J28: Gold | K28: =IF(J28="","Platinum",J28) -> Gold
A29: CUST1027 | B29: Leslie Johnson | C29: =PROPER(TRIM(B29)) -> Leslie Johnson | D29: 31 | E29: Male | F29: Mollyshire | G29: =PROPER(TRIM(F29)) -> Mollyshire | H29: Utah | I29: USA | K29: =IF(J29="","Platinum",J29) -> Platinum
A30: CUST1028 | B30: Joshua Ryan | C30: =PROPER(TRIM(B30)) -> Joshua Ryan | D30: 27 | E30: Female | F30: New David | G30: =PROPER(TRIM(F30)) -> New David | H30: New Jersey | I30: USA | J30: Platinum | K30: =IF(J30="","Platinum",J30) -> Platinum
A31: CUST1029 | B31: David Arnold | C31: =PROPER(TRIM(B31)) -> David Arnold | D31: 54 | E31: Female | F31: East Jennifer | G31: =PROPER(TRIM(F31)) -> East Jennifer | H31: California | I31: USA | J31: Silver | K31: =IF(J31="","Platinum",J31) -> Silver
A32: CUST1030 | B32: Jessica Acevedo | C32: =PROPER(TRIM(B32)) -> Jessica Acevedo | D32: 64 | E32: Female | F32: Amybury | G32: =PROPER(TRIM(F32)) -> Amybury | H32: Pennsylvania | I32: USA | J32: Bronze | K32: =IF(J32="","Platinum",J32) -> Bronze
A33: CUST1031 | B33: Sarah Vance | C33: =PROPER(TRIM(B33)) -> Sarah Vance | D33: 41 | E33: Male | F33: Johnsonville | G33: =PROPER(TRIM(F33)) -> Johnsonville | H33: Oregon | I33: USA | J33: Silver | K33: =IF(J33="","Platinum",J33) -> Silver
A34: CUST1032 | B34: Mike Jennings | C34: =PROPER(TRIM(B34)) -> Mike Jennings | D34: 48 | E34: Female | F34: Fostermouth | G34: =PROPER(TRIM(F34)) -> Fostermouth | H34: Arizona | I34: USA | J34: Gold | K34: =IF(J34="","Platinum",J34) -> Gold
A35: CUST1033 | B35: Robert Jones DDS | C35: =PROPER(TRIM(B35)) -> Robert Jones Dds | D35: 25 | E35: Male | F35: Tristanton | G35: =PROPER(TRIM(F35)) -> Tristanton | H35: Oklahoma | I35: USA | J35: Platinum | K35: =IF(J35="","Platinum",J35) -> Platinum
A36: CUST1034 | B36: Christopher Olson | C36: =PROPER(TRIM(B36)) -> Christopher Olson | D36: 27 | E36: Female | F36: West Richard | G36: =PROPER(TRIM(F36)) -> West Richard | H36: Maryland | I36: USA | J36: Platinum | K36: =IF(J36="","Platinum",J36) -> Platinum
A37: CUST1035 | B37: Rachel Myers | C37: =PROPER(TRIM(B37)) -> Rachel Myers | D37: 52 | E37: Male | F37: Robertberg | G37: =PROPER(TRIM(F37)) -> Robertberg | H37: North Dakota | I37: USA | J37: Silver | K37: =IF(J37="","Platinum",J37) -> Silver
A38: CUST1036 | B38: Thomas Phillips | C38: =PROPER(TRIM(B38)) -> Thomas Phillips | D38: 20 | E38: Female | F38: Luisfurt | G38: =PROPER(TRIM(F38)) -> Luisfurt | H38: Georgia | I38: USA | J38: Gold | K38: =IF(J38="","Platinum",J38) -> Gold
A39: CUST1037 | B39: Christopher Carter | C39: =PROPER(TRIM(B39)) -> Christopher Carter | D39: 27 | E39: Female | F39: Brendastad | G39: =PROPER(TRIM(F39)) -> Brendastad | H39: South Dakota | I39: USA | K39: =IF(J39="","Platinum",J39) -> Platinum
A40: CUST1038 | B40: Deanna Simpson | C40: =PROPER(TRIM(B40)) -> Deanna Simpson | D40: 35 | E40: Female | F40: Brownport | G40: =PROPER(TRIM(F40)) -> Brownport | H40: North Dakota | I40: USA | J40: Bronze | K40: =IF(J40="","Platinum",J40) -> Bronze
A41: CUST1039 | B41: Tonya Reynolds | C41: =PROPER(TRIM(B41)) -> Tonya Reynolds | D41: 55 | E41: Female | F41: Darleneton | G41: =PROPER(TRIM(F41)) -> Darleneton | H41: Michigan | I41: USA | J41: Gold | K41: =IF(J41="","Platinum",J41) -> Gold
A42: CUST1040 | B42: Eric Vega | C42: =PROPER(TRIM(B42)) -> Eric Vega | D42: 50 | E42: Male | F42: Williamsonland | G42: =PROPER(TRIM(F42)) -> Williamsonland | H42: Kansas | I42: USA | J42: Gold | K42: =IF(J42="","Platinum",J42) -> Gold
A43: CUST1041 | B43: James Gibbs | C43: =PROPER(TRIM(B43)) -> James Gibbs | D43: 21 | E43: Male | F43: Mooneyshire | G43: =PROPER(TRIM(F43)) -> Mooneyshire | H43: Alaska | I43: USA | J43: Platinum | K43: =IF(J43="","Platinum",J43) -> Platinum
A44: CUST1042 | B44: William Martin | C44: =PROPER(TRIM(B44)) -> William Martin | D44: 19 | E44: Male | F44: Ryanburgh | G44: =PROPER(TRIM(F44)) -> Ryanburgh | H44: Connecticut | I44: USA | J44: Platinum | K44: =IF(J44="","Platinum",J44) -> Platinum
...

Sheet Customer_Dim_Cleaned
A1: Customer_ID | B1: Name | C1: Age | D1: Gender | E1: City | F1: State | G1: Country | H1: Loyalty_Level
A2: CUST1000 | B2: Sheena Bonilla | C2: 55 | D2: Male | E2: Donaldton | F2: North Carolina | G2: USA | H2: Platinum
A3: CUST1001 | B3: Eugene Nelson | C3: 26 | D3: Female | E3: Phillipsmouth | F3: North Dakota | G3: USA | H3: Platinum
A4: CUST1002 | B4: Dr. Benjamin Price | C4: 29 | D4: Female | E4: Kylebury | F4: Alabama | G4: USA | H4: Platinum
A5: CUST1003 | B5: Jeremy Harris | C5: 59 | D5: Female | E5: Thomastown | F5: Ohio | G5: USA | H5: Bronze
A6: CUST1004 | B6: Caroline Collins | C6: 64 | D6: Female | E6: Nicholasshire | F6: California | G6: USA | H6: Silver
A7: CUST1005 | B7: Christine Vaughn | C7: 24 | D7: Male | E7: East Amandamouth | F7: Oregon | G7: USA | H7: Bronze
A8: CUST1006 | B8: Amber Jackson | C8: 29 | D8: Female | E8: Deborahborough | F8: South Dakota | G8: USA | H8: Platinum
A9: CUST1007 | B9: Daniel Boyd | C9: 29 | D9: Female | E9: West Pamelafurt | F9: West Virginia | G9: USA | H9: Bronze
A10: CUST1008 | B10: Melissa Howard | C10: 53 | D10: Female | E10: Maynardton | F10: New Hampshire | G10: USA | H10: Gold
A11: CUST1009 | B11: Ms. Maria Leach | C11: 64 | D11: Male | E11: Melissashire | F11: Pennsylvania | G11: USA | H11: Platinum
A12: CUST1010 | B12: Dominic Page | C12: 53 | D12: Male | E12: Port Michaelburgh | F12: Pennsylvania | G12: USA | H12: Bronze
A13: CUST1011 | B13: Brian Lopez | C13: 28 | D13: Female | E13: East Krista | F13: New York | G13: USA | H13: Gold
... A501: CUST1499 | B501: Philip Pennington | C501: 27 | D501: Female | E501: East Valerieview | F501: Oregon | G501: USA | H501: Platinum

Sheet Product_Dim
A1: Product_ID | B1: Product_Name | C1: Category | D1: Sub_Category | E1: Brand | F1: Cost | G1: Stock
A2: PROD0 | B2: Brother Laser Printer | C2: Electronics | D2: Computer | E2: Hunt Inc | F2: 112.42 | G2: 416
A3: PROD1 | B3: Men's Graphic T-Shirt | C3: Clothing | D3: Tops | E3: Terry-Moore | F3: 342.56 | G3: 181
A4: PROD2 | B4: Women's Casual Hoodie | C4: Clothing | D4: Outerwear | E4: Sims Inc | G4: 352
A5: P-3 | B5: Men's Running Jacket | C5: Clothing | D5: Outerwear | E5: Pineda Ltd | F5: 364.67 | G5: 452
A6: PROD4 | B6: Women's Yoga Pants | C6: Clothing | D6: Bottoms | E6: Gonzales-Davis | F6: 306.46 | G6: 487
A7: PROD5 | B7: Men's Leather Belt | C7: Clothing | D7: Accessories | E7: Baldwin, Garza and Gonzalez | F7: 261 | G7: 59
A8: PROD6 | B8: Herbal Face Moisturizer | C8: Beauty | D8: Skincare | E8: Davidson PLC | F8: 312.8 | G8: 350
A9: PROD7 | B9: LED Table Lamp | C9: Home | D9: Lighting | E9: Harrell LLC | F9: 218.86 | G9: 170
A10: PROD8 | B10: Wireless Bluetooth Earbuds | C10: Electronics | D10: Audio | E10: Perez-Johnston | F10: 439.07 | G10: 142
A11: PROD9 | B11: Adjustable Dumbbell Set | C11: Sports | D11: Fitness | E11: Hill PLC | F11: 495.72 | G11: 323
A12: PROD10 | B12: Ceramic Kitchen Bowl Set | C12: Home | D12: Kitchen | E12: Hamilton Group | F12: 298.86 | G12: 308
A13: PROD11 | B13: HD Smart TV Stick | C13: Electronics | D13: Accessories | E13: Gibson, Hobbs and Weaver | F13: 449.4
A14: PROD12 | B14: Hair Strengthening Shampoo | C14: Beauty | D14: Haircare | E14: Rice LLC | F14: 115.82 | G14: 460
A15: PROD13 | B15: USB-C Fast Charger | C15: Electronics | D15: Accessories | E15: Dawson-Perkins | F15: 242.23 | G15: 453
A16: PROD14 | B16: Decorative Wall Mirror | C16: Home | D16: Decor | E16: Luna, Anderson and Bowman | F16: 48.01 | G16: 439
A17: PROD15 | B17: 4K Home Projector | C17: Electronics | D17: Appliances | E17: Thomas LLC | F17: 465.34 | G17: 301
A18: P-16 | B18: Beard Grooming Kit | C18: Beauty | D18: Grooming | E18: Erickson-Green | F18: 337.42 | G18: 256
A19: PROD17 | B19: Soccer Training Cone Set | C19: Sports | D19: Accessories | E19: Ford, Murphy and Wilson | F19: 144.53 | G19: 367
A20: PROD18 | B20: Women's Denim Jeans | C20: Clothing | D20: Bottoms | E20: Guerra-Hendrix | G20: 343
A21: PROD19 | B21: Knee Support Brace | C21: Sports | D21: Equipment | E21: May-Reese | F21: 21.34 | G21: 65
A22: PROD20 | B22: Outdoor Sports Water Bottle | C22: Sports | D22: Accessories | E22: Soto-Ellis | F22: 131.51
A23: PROD21 | B23: Multi-Purpose Storage Box | C23: Home | D23: Storage | E23: Gardner-Montes | F23: 123.46 | G23: 76
A24: PROD22 | B24: Carbon Fiber Tennis Racket | C24: Sports | D24: Equipment | E24: Flores, Pineda and Rodriguez | F24: 484.62 | G24: 432
A25: PROD23 | B25: Men's Formal Shirt | C25: Clothing | D25: Tops | E25: Moon, Mora and Santos | G25: 360
A26: PROD24 | B26: Foldable Camping Chair | C26: Sports | D26: Outdoor | E26: Cook Ltd | F26: 166.06 | G26: 340
A27: PROD25 | B27: Women's Scarf Set | C27: Clothing | D27: Accessories | E27: Brown and Sons | F27: 174.02 | G27: 268
A28: PROD26 | B28: Wireless Bluetooth Speaker | C28: Electronics | D28: Audio | E28: Reed-Schmidt | F28: 322.41 | G28: 213
A29: PROD27 | B29: Decorative Floor Vase | C29: Home | D29: Decor | E29: Khan, Jones and Paul | G29: 378
A30: PROD28 | B30: Sports Stopwatch Timer | C30: Sports | D30: Accessories | E30: Burns-Hansen | F30: 38.76 | G30: 137
A31: PROD29 | B31: Fabric Sofa Throw Blanket | C31: Home | D31: Decor | E31: Hoffman Group | F31: 218.48 | G31: 276
A32: PROD30 | B32: Stainless Steel Cutlery Set | C32: Home | D32: Kitchen | E32: Stevens, Fernandez and Martin | F32: 19.52 | G32: 57
A33: PROD31 | B33: Basketball | C33: Sports | D33: Team Sports | E33: Nolan-Snow | F33: 204.39 | G33: 281
A34: PROD32 | B34: Vitamin C Face Serum | C34: Beauty | D34: Skincare | E34: Griffin Ltd | F34: 283.83 | G34: 244
A35: PROD33 | B35: Modern Wall Clock | C35: Home | D35: Decor | E35: Weiss-Watson | F35: 179.77 | G35: 305
A36: PROD34 | B36: Gaming Mechanical Keyboard | C36: Electronics | D36: Computer | E36: Lucero LLC | F36: 419.28 | G36: 86
A37: PROD35 | B37: Bedroom Table Lamp | C37: Home | D37: Lighting | E37: Jones LLC | F37: 382.22 | G37: 329
A38: PROD36 | B38: Women's Summer Dress | C38: Clothing | D38: Tops | E38: Smith-Mills | F38: 223.43 | G38: 154
A39: PROD37 | B39: Men's Casual Sneakers | C39: Clothing | D39: Footwear | E39: Hogan-Lee | F39: 353.47 | G39: 214
A40: PROD38 | B40: Sports Water Hydration Pack | C40: Sports | D40: Outdoor | E40: Sims-Smith | F40: 135.61 | G40: 394
...

Sheet Product_Dim_Cleaning
A1: Product_ID | B1: Product_Name | C1: Category | D1: Sub_Category | E1: Brand | F1: Cost | G1: Cost2 | H1: Stock | I1: Stock2
A2: PROD0 | B2: Brother Laser Printer | C2: Electronics | D2: Computer | E2: Hunt Inc | F2: 112.42 | G2: =IF(ISBLANK(F2),AVERAGEIF($C$2:$C$101,C2,$F$2:$F$101),F2) -> 112.42 | H2: 416 | I2: =IF(H2="",AVERAGEIF($D$2:$D$101,D2,$H$2:$H$101),H2) -> 416
A3: PROD1 | B3: Men's Graphic T-Shirt | C3: Clothing | D3: Tops | E3: Terry-Moore | F3: 342.56 | G3: =IF(ISBLANK(F3),AVERAGEIF($C$2:$C$101,C3,$F$2:$F$101),F3) -> 342.56 | H3: 181 | I3: =IF(H3="",AVERAGEIF($D$2:$D$101,D3,$H$2:$H$101),H3) -> 181
A4: PROD2 | B4: Women's Casual Hoodie | C4: Clothing | D4: Outerwear | E4: Sims Inc | G4: =IF(ISBLANK(F4),AVERAGEIF($C$2:$C$101,C4,$F$2:$F$101),F4) -> 265.73267 | H4: 352 | I4: =IF(H4="",AVERAGEIF($D$2:$D$101,D4,$H$2:$H$101),H4) -> 352
A5: PROD3 | B5: Men's Running Jacket | C5: Clothing | D5: Outerwear | E5: Pineda Ltd | F5: 364.67 | G5: =IF(ISBLANK(F5),AVERAGEIF($C$2:$C$101,C5,$F$2:$F$101),F5) -> 364.67 | H5: 452 | I5: =IF(H5="",AVERAGEIF($D$2:$D$101,D5,$H$2:$H$101),H5) -> 452
A6: PROD4 | B6: Women's Yoga Pants | C6: Clothing | D6: Bottoms | E6: Gonzales-Davis | F6: 306.46 | G6: =IF(ISBLANK(F6),AVERAGEIF($C$2:$C$101,C6,$F$2:$F$101),F6) -> 306.46 | H6: 487 | I6: =IF(H6="",AVERAGEIF($D$2:$D$101,D6,$H$2:$H$101),H6) -> 487
A7: PROD5 | B7: Men's Leather Belt | C7: Clothing | D7: Accessories | E7: Baldwin, Garza and Gonzalez | F7: 261 | G7: =IF(ISBLANK(F7),AVERAGEIF($C$2:$C$101,C7,$F$2:$F$101),F7) -> 261 | H7: 59 | I7: =IF(H7="",AVERAGEIF($D$2:$D$101,D7,$H$2:$H$101),H7) -> 59
A8: PROD6 | B8: Herbal Face Moisturizer | C8: Beauty | D8: Skincare | E8: Davidson PLC | F8: 312.8 | G8: =IF(ISBLANK(F8),AVERAGEIF($C$2:$C$101,C8,$F$2:$F$101),F8) -> 312.8 | H8: 350 | I8: =IF(H8="",AVERAGEIF($D$2:$D$101,D8,$H$2:$H$101),H8) -> 350
A9: PROD7 | B9: LED Table Lamp | C9: Home | D9: Lighting | E9: Harrell LLC | F9: 218.86 | G9: =IF(ISBLANK(F9),AVERAGEIF($C$2:$C$101,C9,$F$2:$F$101),F9) -> 218.86 | H9: 170 | I9: =IF(H9="",AVERAGEIF($D$2:$D$101,D9,$H$2:$H$101),H9) -> 170
A10: PROD8 | B10: Wireless Bluetooth Earbuds | C10: Electronics | D10: Audio | E10: Perez-Johnston | F10: 439.07 | G10: =IF(ISBLANK(F10),AVERAGEIF($C$2:$C$101,C10,$F$2:$F$101),F10) -> 439.07 | H10: 142 | I10: =IF(H10="",AVERAGEIF($D$2:$D$101,D10,$H$2:$H$101),H10) -> 142
A11: PROD9 | B11: Adjustable Dumbbell Set | C11: Sports | D11: Fitness | E11: Hill PLC | F11: 495.72 | G11: =IF(ISBLANK(F11),AVERAGEIF($C$2:$C$101,C11,$F$2:$F$101),F11) -> 495.72 | H11: 323 | I11: =IF(H11="",AVERAGEIF($D$2:$D$101,D11,$H$2:$H$101),H11) -> 323
A12: PROD10 | B12: Ceramic Kitchen Bowl Set | C12: Home | D12: Kitchen | E12: Hamilton Group | F12: 298.86 | G12: =IF(ISBLANK(F12),AVERAGEIF($C$2:$C$101,C12,$F$2:$F$101),F12) -> 298.86 | H12: 308 | I12: =IF(H12="",AVERAGEIF($D$2:$D$101,D12,$H$2:$H$101),H12) -> 308
A13: PROD11 | B13: HD Smart TV Stick | C13: Electronics | D13: Accessories | E13: Gibson, Hobbs and Weaver | F13: 449.4 | G13: =IF(ISBLANK(F13),AVERAGEIF($C$2:$C$101,C13,$F$2:$F$101),F13) -> 449.4 | I13: =IF(H13="",AVERAGEIF($D$2:$D$101,D13,$H$2:$H$101),H13) -> 269.73333
A14: PROD12 | B14: Hair Strengthening Shampoo | C14: Beauty | D14: Haircare | E14: Rice LLC | F14: 115.82 | G14: =IF(ISBLANK(F14),AVERAGEIF($C$2:$C$101,C14,$F$2:$F$101),F14) -> 115.82 | H14: 460 | I14: =IF(H14="",AVERAGEIF($D$2:$D$101,D14,$H$2:$H$101),H14) -> 460
A15: PROD13 | B15: USB-C Fast Charger | C15: Electronics | D15: Accessories | E15: Dawson-Perkins | F15: 242.23 | G15: =IF(ISBLANK(F15),AVERAGEIF($C$2:$C$101,C15,$F$2:$F$101),F15) -> 242.23 | H15: 453 | I15: =IF(H15="",AVERAGEIF($D$2:$D$101,D15,$H$2:$H$101),H15) -> 453
A16: PROD14 | B16: Decorative Wall Mirror | C16: Home | D16: Decor | E16: Luna, Anderson and Bowman | F16: 48.01 | G16: =IF(ISBLANK(F16),AVERAGEIF($C$2:$C$101,C16,$F$2:$F$101),F16) -> 48.01 | H16: 439 | I16: =IF(H16="",AVERAGEIF($D$2:$D$101,D16,$H$2:$H$101),H16) -> 439
A17: PROD15 | B17: 4K Home Projector | C17: Electronics | D17: Appliances | E17: Thomas LLC | F17: 465.34 | G17: =IF(ISBLANK(F17),AVERAGEIF($C$2:$C$101,C17,$F$2:$F$101),F17) -> 465.34 | H17: 301 | I17: =IF(H17="",AVERAGEIF($D$2:$D$101,D17,$H$2:$H$101),H17) -> 301
A18: PROD16 | B18: Beard Grooming Kit | C18: Beauty | D18: Grooming | E18: Erickson-Green | F18: 337.42 | G18: =IF(ISBLANK(F18),AVERAGEIF($C$2:$C$101,C18,$F$2:$F$101),F18) -> 337.42 | H18: 256 | I18: =IF(H18="",AVERAGEIF($D$2:$D$101,D18,$H$2:$H$101),H18) -> 256
A19: PROD17 | B19: Soccer Training Cone Set | C19: Sports | D19: Accessories | E19: Ford, Murphy and Wilson | F19: 144.53 | G19: =IF(ISBLANK(F19),AVERAGEIF($C$2:$C$101,C19,$F$2:$F$101),F19) -> 144.53 | H19: 367 | I19: =IF(H19="",AVERAGEIF($D$2:$D$101,D19,$H$2:$H$101),H19) -> 367
A20: PROD18 | B20: Women's Denim Jeans | C20: Clothing | D20: Bottoms | E20: Guerra-Hendrix | G20: =IF(ISBLANK(F20),AVERAGEIF($C$2:$C$101,C20,$F$2:$F$101),F20) -> 265.73267 | H20: 343 | I20: =IF(H20="",AVERAGEIF($D$2:$D$101,D20,$H$2:$H$101),H20) -> 343
A21: PROD19 | B21: Knee Support Brace | C21: Sports | D21: Equipment | E21: May-Reese | F21: 21.34 | G21: =IF(ISBLANK(F21),AVERAGEIF($C$2:$C$101,C21,$F$2:$F$101),F21) -> 21.34 | H21: 65 | I21: =IF(H21="",AVERAGEIF($D$2:$D$101,D21,$H$2:$H$101),H21) -> 65
A22: PROD20 | B22: Outdoor Sports Water Bottle | C22: Sports | D22: Accessories | E22: Soto-Ellis | F22: 131.51 | G22: =IF(ISBLANK(F22),AVERAGEIF($C$2:$C$101,C22,$F$2:$F$101),F22) -> 131.51 | I22: =IF(H22="",AVERAGEIF($D$2:$D$101,D22,$H$2:$H$101),H22) -> 269.73333
A23: PROD21 | B23: Multi-Purpose Storage Box | C23: Home | D23: Storage | E23: Gardner-Montes | F23: 123.46 | G23: =IF(ISBLANK(F23),AVERAGEIF($C$2:$C$101,C23,$F$2:$F$101),F23) -> 123.46 | H23: 76 | I23: =IF(H23="",AVERAGEIF($D$2:$D$101,D23,$H$2:$H$101),H23) -> 76
A24: PROD22 | B24: Carbon Fiber Tennis Racket | C24: Sports | D24: Equipment | E24: Flores, Pineda and Rodriguez | F24: 484.62 | G24: =IF(ISBLANK(F24),AVERAGEIF($C$2:$C$101,C24,$F$2:$F$101),F24) -> 484.62 | H24: 432 | I24: =IF(H24="",AVERAGEIF($D$2:$D$101,D24,$H$2:$H$101),H24) -> 432
A25: PROD23 | B25: Men's Formal Shirt | C25: Clothing | D25: Tops | E25: Moon, Mora and Santos | G25: =IF(ISBLANK(F25),AVERAGEIF($C$2:$C$101,C25,$F$2:$F$101),F25) -> 265.73267 | H25: 360 | I25: =IF(H25="",AVERAGEIF($D$2:$D$101,D25,$H$2:$H$101),H25) -> 360
A26: PROD24 | B26: Foldable Camping Chair | C26: Sports | D26: Outdoor | E26: Cook Ltd | F26: 166.06 | G26: =IF(ISBLANK(F26),AVERAGEIF($C$2:$C$101,C26,$F$2:$F$101),F26) -> 166.06 | H26: 340 | I26: =IF(H26="",AVERAGEIF($D$2:$D$101,D26,$H$2:$H$101),H26) -> 340
A27: PROD25 | B27: Women's Scarf Set | C27: Clothing | D27: Accessories | E27: Brown and Sons | F27: 174.02 | G27: =IF(ISBLANK(F27),AVERAGEIF($C$2:$C$101,C27,$F$2:$F$101),F27) -> 174.02 | H27: 268 | I27: =IF(H27="",AVERAGEIF($D$2:$D$101,D27,$H$2:$H$101),H27) -> 268
A28: PROD26 | B28: Wireless Bluetooth Speaker | C28: Electronics | D28: Audio | E28: Reed-Schmidt | F28: 322.41 | G28: =IF(ISBLANK(F28),AVERAGEIF($C$2:$C$101,C28,$F$2:$F$101),F28) -> 322.41 | H28: 213 | I28: =IF(H28="",AVERAGEIF($D$2:$D$101,D28,$H$2:$H$101),H28) -> 213
A29: PROD27 | B29: Decorative Floor Vase | C29: Home | D29: Decor | E29: Khan, Jones and Paul | G29: =IF(ISBLANK(F29),AVERAGEIF($C$2:$C$101,C29,$F$2:$F$101),F29) -> 234.806 | H29: 378 | I29: =IF(H29="",AVERAGEIF($D$2:$D$101,D29,$H$2:$H$101),H29) -> 378
A30: PROD28 | B30: Sports Stopwatch Timer | C30: Sports | D30: Accessories | E30: Burns-Hansen | F30: 38.76 | G30: =IF(ISBLANK(F30),AVERAGEIF($C$2:$C$101,C30,$F$2:$F$101),F30) -> 38.76 | H30: 137 | I30: =IF(H30="",AVERAGEIF($D$2:$D$101,D30,$H$2:$H$101),H30) -> 137
A31: PROD29 | B31: Fabric Sofa Throw Blanket | C31: Home | D31: Decor | E31: Hoffman Group | F31: 218.48 | G31: =IF(ISBLANK(F31),AVERAGEIF($C$2:$C$101,C31,$F$2:$F$101),F31) -> 218.48 | H31: 276 | I31: =IF(H31="",AVERAGEIF($D$2:$D$101,D31,$H$2:$H$101),H31) -> 276
A32: PROD30 | B32: Stainless Steel Cutlery Set | C32: Home | D32: Kitchen | E32: Stevens, Fernandez and Martin | F32: 19.52 | G32: =IF(ISBLANK(F32),AVERAGEIF($C$2:$C$101,C32,$F$2:$F$101),F32) -> 19.52 | H32: 57 | I32: =IF(H32="",AVERAGEIF($D$2:$D$101,D32,$H$2:$H$101),H32) -> 57
A33: PROD31 | B33: Basketball | C33: Sports | D33: Team Sports | E33: Nolan-Snow | F33: 204.39 | G33: =IF(ISBLANK(F33),AVERAGEIF($C$2:$C$101,C33,$F$2:$F$101),F33) -> 204.39 | H33: 281 | I33: =IF(H33="",AVERAGEIF($D$2:$D$101,D33,$H$2:$H$101),H33) -> 281
A34: PROD32 | B34: Vitamin C Face Serum | C34: Beauty | D34: Skincare | E34: Griffin Ltd | F34: 283.83 | G34: =IF(ISBLANK(F34),AVERAGEIF($C$2:$C$101,C34,$F$2:$F$101),F34) -> 283.83 | H34: 244 | I34: =IF(H34="",AVERAGEIF($D$2:$D$101,D34,$H$2:$H$101),H34) -> 244
A35: PROD33 | B35: Modern Wall Clock | C35: Home | D35: Decor | E35: Weiss-Watson | F35: 179.77 | G35: =IF(ISBLANK(F35),AVERAGEIF($C$2:$C$101,C35,$F$2:$F$101),F35) -> 179.77 | H35: 305 | I35: =IF(H35="",AVERAGEIF($D$2:$D$101,D35,$H$2:$H$101),H35) -> 305
A36: PROD34 | B36: Gaming Mechanical Keyboard | C36: Electronics | D36: Computer | E36: Lucero LLC | F36: 419.28 | G36: =IF(ISBLANK(F36),AVERAGEIF($C$2:$C$101,C36,$F$2:$F$101),F36) -> 419.28 | H36: 86 | I36: =IF(H36="",AVERAGEIF($D$2:$D$101,D36,$H$2:$H$101),H36) -> 86
A37: PROD35 | B37: Bedroom Table Lamp | C37: Home | D37: Lighting | E37: Jones LLC | F37: 382.22 | G37: =IF(ISBLANK(F37),AVERAGEIF($C$2:$C$101,C37,$F$2:$F$101),F37) -> 382.22 | H37: 329 | I37: =IF(H37="",AVERAGEIF($D$2:$D$101,D37,$H$2:$H$101),H37) -> 329
A38: PROD36 | B38: Women's Summer Dress | C38: Clothing | D38: Tops | E38: Smith-Mills | F38: 223.43 | G38: =IF(ISBLANK(F38),AVERAGEIF($C$2:$C$101,C38,$F$2:$F$101),F38) -> 223.43 | H38: 154 | I38: =IF(H38="",AVERAGEIF($D$2:$D$101,D38,$H$2:$H$101),H38) -> 154
A39: PROD37 | B39: Men's Casual Sneakers | C39: Clothing | D39: Footwear | E39: Hogan-Lee | F39: 353.47 | G39: =IF(ISBLANK(F39),AVERAGEIF($C$2:$C$101,C39,$F$2:$F$101),F39) -> 353.47 | H39: 214 | I39: =IF(H39="",AVERAGEIF($D$2:$D$101,D39,$H$2:$H$101),H39) -> 214
A40: PROD38 | B40: Sports Water Hydration Pack | C40: Sports | D40: Outdoor | E40: Sims-Smith | F40: 135.61 | G40: =IF(ISBLANK(F40),AVERAGEIF($C$2:$C$101,C40,$F$2:$F$101),F40) -> 135.61 | H40: 394 | I40: =IF(H40="",AVERAGEIF($D$2:$D$101,D40,$H$2:$H$101),H40) -> 394
...

Sheet Product_Dim_Cleaned
A1: Product_ID | B1: Product_Name | C1: Category | D1: Sub_Category | E1: Brand | F1: Cost | G1: Stock
A2: PROD0 | B2: Brother Laser Printer | C2: Electronics | D2: Computer | E2: Hunt Inc | F2: 112.42 | G2: 416
A3: PROD1 | B3: Men's Graphic T-Shirt | C3: Clothing | D3: Tops | E3: Terry-Moore | F3: 342.56 | G3: 181
A4: PROD2 | B4: Women's Casual Hoodie | C4: Clothing | D4: Outerwear | E4: Sims Inc | F4: 265.73267 | G4: 352
A5: PROD3 | B5: Men's Running Jacket | C5: Clothing | D5: Outerwear | E5: Pineda Ltd | F5: 364.67 | G5: 452
A6: PROD4 | B6: Women's Yoga Pants | C6: Clothing | D6: Bottoms | E6: Gonzales-Davis | F6: 306.46 | G6: 487
A7: PROD5 | B7: Men's Leather Belt | C7: Clothing | D7: Accessories | E7: Baldwin, Garza and Gonzalez | F7: 261 | G7: 59
A8: PROD6 | B8: Herbal Face Moisturizer | C8: Beauty | D8: Skincare | E8: Davidson PLC | F8: 312.8 | G8: 350
A9: PROD7 | B9: LED Table Lamp | C9: Home | D9: Lighting | E9: Harrell LLC | F9: 218.86 | G9: 170
A10: PROD8 | B10: Wireless Bluetooth Earbuds | C10: Electronics | D10: Audio | E10: Perez-Johnston | F10: 439.07 | G10: 142
A11: PROD9 | B11: Adjustable Dumbbell Set | C11: Sports | D11: Fitness | E11: Hill PLC | F11: 495.72 | G11: 323
A12: PROD10 | B12: Ceramic Kitchen Bowl Set | C12: Home | D12: Kitchen | E12: Hamilton Group | F12: 298.86 | G12: 308
A13: PROD11 | B13: HD Smart TV Stick | C13: Electronics | D13: Accessories | E13: Gibson, Hobbs and Weaver | F13: 449.4 | G13: 269.73333
... A101: PROD99 | B101: Stainless Steel Cookware Set | C101: Home | D101: Kitchen | E101: Campbell Ltd | F101: 201.41 | G101: 146

Sheet Store_Dim
A1: Store_ID | B1: Store_Name | C1: Region | D1: City | E1: Store_Type
A2: STORE0 | B2: Rivera-Warner | C2: East | D2: Washingtonfurt | E2: Flagship
A3: STORE1 | B3: Martinez, Adkins and Johnson | C3: North | D3: Danielmouth | E3: Flagship
A4: STORE2 | B4: Black-Horn | C4: South | D4: North Nancyview | E4: Outlet
A5: STORE3 | B5: Johnson-Wright | C5: North | D5: Hoodberg | E5: Outlet
A6: STORE4 | B6: Alexander Group | C6: South | D6: Port Sharon | E6: Online
A7: STORE5 | B7: Gray Ltd | C7: North | D7: New Michaelchester | E7: Outlet
A8: STORE6 | B8: Benson-Elliott | C8: East | D8: Port Josephberg | E8: Online
A9: STORE7 | B9: Martinez-Mullins | C9: South | D9: Williamsfurt | E9: Online
A10: STORE8 | B10: Bean, Jones and Park | C10: West | D10: Thompsonborough | E10: Online
A11: STORE9 | B11: Moore, Padilla and Butler | C11: South | D11: East Johnstad | E11: Flagship
A12: STORE10 | B12: Hill, Wagner and Ballard | C12: East | D12: East Davidville | E12: Online
... A21: STORE19 | B21: Mann-Austin | C21: East | D21: Vasquezborough | E21: Online

Sheet Store_Dim_Cleaned
A1: Store_ID | B1: Store_Name | C1: Region | D1: City | E1: Store_Type
A2: STORE0 | B2: Rivera-Warner | C2: East | D2: Washingtonfurt | E2: Flagship
A3: STORE1 | B3: Martinez, Adkins and Johnson | C3: North | D3: Danielmouth | E3: Flagship
A4: STORE2 | B4: Black-Horn | C4: South | D4: North Nancyview | E4: Outlet
A5: STORE3 | B5: Johnson-Wright | C5: North | D5: Hoodberg | E5: Outlet
A6: STORE4 | B6: Alexander Group | C6: South | D6: Port Sharon | E6: Online
A7: STORE5 | B7: Gray Ltd | C7: North | D7: New Michaelchester | E7: Outlet
A8: STORE6 | B8: Benson-Elliott | C8: East | D8: Port Josephberg | E8: Online
A9: STORE7 | B9: Martinez-Mullins | C9: South | D9: Williamsfurt | E9: Online
A10: STORE8 | B10: Bean, Jones and Park | C10: West | D10: Thompsonborough | E10: Online
A11: STORE9 | B11: Moore, Padilla and Butler | C11: South | D11: East Johnstad | E11: Flagship
A12: STORE10 | B12: Hill, Wagner and Ballard | C12: East | D12: East Davidville | E12: Online
... A21: STORE19 | B21: Mann-Austin | C21: East | D21: Vasquezborough | E21: Online

Sheet Sales_Fact
A1: Sales_ID | B1: Order_Date | C1: Customer_ID | D1: Product_ID | E1: Store_ID | F1: Quantity | G1: Unit_Price | H1: Discount | I1: Payment_Type | J1: Total_Amount
A2: SALE0 | B2: 45480 | C2: CUST1409 | D2: PROD97 | E2: STORE3 | F2: 1 | G2: 218.04 | H2: 0.09 | I2: Credit Card | J2: 198.4164
A3: SALE1 | B3: 45285 | C3: CUST1467 | D3: PROD74 | E3: STORE17 | F3: 3 | G3: 104.47 | H3: 0.27 | I3: PayPal | J3: 228.7893
A4: SALE2 | B4: 45446 | C4: CUST1056 | D4: PROD49 | E4: STORE8 | F4: 4 | G4: 914.05 | H4: 0.25 | I4: Credit Card | J4: 2742.15
A5: SALE3 | B5: 45259 | C5: CUST1346 | D5: PROD76 | E5: STORE8 | F5: 1 | G5: 921.51 | H5: 0.16 | I5: COD | J5: 774.0684
A6: SALE4 | B6: 45297 | C6: CUST1493 | D6: PROD59 | E6: STORE5 | F6: 3 | G6: 745.3 | H6: 0.18 | I6: Credit Card | J6: 1833.438
A7: SALE5 | B7: 45499 | C7: CUST1116 | D7: PROD15 | E7: STORE7 | F7: 3 | G7: 147.01 | H7: 0.19 | I7: COD | J7: 357.2343
A8: SALE6 | B8: 45850 | C8: CUST1016 | D8: PROD56 | E8: STORE4 | F8: 2 | G8: 785.31 | H8: 0.15 | I8: PayPal | J8: 1335.027
A9: SALE7 | B9: 45248 | C9: CUST1152 | D9: PROD70 | E9: STORE8 | F9: 4 | G9: 342.39 | H9: 0.23 | I9: PayPal | J9: 1054.5612
A10: SALE8 | B10: 45781 | C10: CUST1187 | D10: PROD99 | E10: STORE5 | G10: 448.25 | H10: 0.07 | I10: PayPal | J10: 1250.6175
A11: SALE9 | B11: 45869 | C11: CUST1464 | D11: PROD33 | E11: STORE0 | F11: 2 | G11: 873.17 | H11: 0.23 | I11: PayPal | J11: 1344.6818
A12: SALE10 | B12: 45335 | C12: CUST1065 | D12: PROD24 | E12: STORE14 | F12: 1 | G12: 278.63 | H12: 0.07 | I12: Credit Card | J12: 259.1259
A13: SALE11 | B13: 45801 | C13: CUST1320 | D13: PROD39 | E13: STORE1 | F13: 4 | G13: 286.92 | H13: 0.17 | I13: Credit Card | J13: 952.5744
A14: SALE12 | B14: 45528 | C14: CUST1237 | D14: PROD88 | E14: STORE4 | F14: 4 | G14: 644.58 | H14: 0.01 | I14: Credit Card | J14: 2552.5368
A15: SALE13 | B15: 45875 | C15: CUST1443 | D15: PROD34 | E15: STORE16 | F15: 2 | G15: 316.9 | H15: 0.3 | I15: PayPal | J15: 443.66
A16: SALE14 | B16: 45829 | C16: CUST1348 | D16: PROD24 | E16: STORE15 | F16: 4 | G16: 403.47 | H16: 0.29 | I16: PayPal | J16: 1145.8548
A17: SALE15 | B17: 45636 | C17: CUST1435 | D17: PROD36 | E17: STORE9 | G17: 871.34 | H17: 0.04 | I17: COD | J17: 2509.4592
A18: SALE16 | B18: 45913 | C18: CUST1276 | D18: PROD65 | E18: STORE19 | F18: 2 | G18: 451.98 | H18: 0.25 | I18: Credit Card | J18: 677.97
A19: SALE17 | B19: 45637 | C19: CUST1079 | D19: PROD27 | E19: STORE4 | F19: 2 | G19: 502.69 | H19: 0.23 | I19: Credit Card | J19: 774.1426
A20: SALE18 | B20: 45517 | C20: CUST1094 | D20: PROD39 | E20: STORE4 | F20: 2 | G20: 559.23 | H20: 0.25 | I20: COD | J20: 838.845
A21: SALE19 | B21: 45369 | C21: CUST1239 | D21: PROD60 | E21: STORE13 | F21: 4 | H21: 0.04 | I21: COD | J21: 1782.4512
A22: SALE20 | B22: 45843 | C22: CUST1144 | D22: PROD72 | E22: STORE17 | F22: 3 | G22: 986.04 | H22: 0.27 | I22: COD | J22: 2159.4276
A23: SALE21 | B23: 45447 | C23: CUST1396 | D23: PROD43 | E23: STORE18 | F23: 1 | G23: 589.56 | H23: 0.22 | I23: Credit Card | J23: 459.8568
A24: SALE22 | B24: 45394 | C24: CUST1476 | D24: PROD69 | E24: STORE10 | F24: 3 | G24: 979.42 | H24: 0.03 | I24: PayPal | J24: 2850.1122
A25: SALE23 | B25: 45466 | C25: CUST1368 | D25: PROD12 | E25: STORE8 | F25: 1 | G25: 719.28 | H25: 0.08 | I25: Credit Card | J25: 661.7376
A26: SALE24 | B26: 45908 | C26: CUST1186 | D26: PROD67 | E26: STORE6 | F26: 3 | G26: 77.6 | H26: 0.07 | I26: Credit Card | J26: 216.504
A27: SALE25 | B27: 45552 | C27: CUST1381 | D27: PROD5 | E27: STORE3 | F27: 4 | G27: 852.71 | H27: 0.14 | I27: PayPal | J27: 2933.3224
A28: SALE26 | B28: 45294 | C28: CUST1213 | D28: PROD98 | E28: STORE8 | F28: 4 | G28: 156.16 | I28: Credit Card | J28: 599.6544
A29: SALE27 | B29: 45710 | C29: CUST1200 | D29: PROD77 | E29: STORE8 | F29: 3 | G29: 815.49 | H29: 0.17 | I29: Credit Card | J29: 2030.5701
A30: SALE28 | B30: 45923 | C30: CUST1148 | D30: PROD13 | E30: STORE2 | F30: 2 | G30: 74.21 | H30: 0.11 | I30: PayPal | J30: 132.0938
A31: SALE29 | B31: 45302 | C31: CUST1348 | D31: PROD99 | E31: STORE3 | G31: 451.67 | H31: 0.15 | I31: Credit Card | J31: 1535.678
A32: SALE30 | B32: 45217 | C32: CUST1028 | D32: PROD5 | E32: STORE19 | F32: 1 | G32: 429.38 | H32: 0.13 | I32: PayPal | J32: 373.5606
A33: SALE31 | B33: 45593 | C33: CUST1412 | D33: PROD53 | E33: STORE12 | F33: 2 | G33: 148.96 | H33: 0.03 | I33: COD | J33: 288.9824
A34: SALE32 | B34: 45597 | C34: CUST1398 | D34: PROD75 | E34: STORE8 | F34: 4 | G34: 313.83 | H34: 0.08 | I34: Credit Card | J34: 1154.8944
A35: SALE33 | B35: 45620 | C35: CUST1453 | D35: PROD12 | E35: STORE6 | F35: 2 | G35: 717.31 | H35: 0.15 | I35: Credit Card | J35: 1219.427
A36: SALE34 | B36: 45215 | C36: CUST1344 | D36: PROD79 | E36: STORE1 | G36: 873.22 | H36: 0.18 | I36: Credit Card | J36: 2148.1212
A37: SALE35 | B37: 45878 | C37: CUST1218 | D37: PROD16 | E37: STORE3 | F37: 4 | G37: 109.36 | H37: 0.19 | I37: COD | J37: 354.3264
A38: SALE36 | B38: 45635 | C38: CUST1086 | D38: PROD5 | E38: STORE7 | F38: 3 | G38: 559.52 | H38: 0.16 | I38: PayPal | J38: 1409.9904
A39: SALE37 | B39: 45329 | C39: CUST1492 | D39: PROD10 | E39: STORE17 | F39: 3 | G39: 121.76 | H39: 0.27 | I39: PayPal | J39: 266.6544
A40: SALE38 | B40: 45378 | C40: CUST1189 | D40: PROD33 | E40: STORE13 | F40: 4 | G40: 735.32 | H40: 0.06 | I40: COD | J40: 2764.8032
...

Sheet Sales_Fact_Cleaning
A1: Sales_ID | B1: Order_Date | C1: Customer_ID | D1: Product_ID | E1: Store_ID | F1: Quantity | G1: Quantity | H1: Unit_Price | I1: Unit_Price | J1: Discount | K1: Discount | L1: Payment_Type | M1: Total_Amount | N1: Total Amount
A2: SALE0 | B2: 45480 | C2: CUST1409 | D2: PROD97 | E2: STORE3 | F2: 1 | G2: =IF(F2="",M2/(I2*(1-J2)),F2) -> 1 | H2: =VLOOKUP(D2,Product_Dim_Cleaned!A:F,6,FALSE) -> 245.98 | I2: =IF(H2="",VLOOKUP($D2,Product_Dim_Cleaned!$A$2:$F$101,6,FALSE),H2) -> 245.98 | J2: 0.09 | K2: =IF(J2="",1-(M2/(G2*I2)),J2) -> 0.09 | L2: Credit Card | M2: 198.4164 | N2: =IF(M2="",G2*I2*(1-K2),M2) -> 198.4164
A3: SALE1 | B3: 45285 | C3: CUST1467 | D3: PROD74 | E3: STORE17 | F3: 3 | G3: =IF(F3="",M3/(I3*(1-J3)),F3) -> 3 | H3: 104.47 | I3: =IF(H3="",VLOOKUP($D3,Product_Dim_Cleaned!$A$2:$F$101,6,FALSE),H3) -> 104.47 | J3: 0.27 | K3: =IF(J3="",1-(M3/(G3*I3)),J3) -> 0.27 | L3: PayPal | M3: 228.7893 | N3: =IF(M3="",G3*I3*(1-K3),M3) -> 228.7893
A4: SALE2 | B4: 45446 | C4: CUST1056 | D4: PROD49 | E4: STORE8 | F4: 4 | G4: =IF(F4="",M4/(I4*(1-J4)),F4) -> 4 | H4: 914.05 | I4: =IF(H4="",VLOOKUP($D4,Product_Dim_Cleaned!$A$2:$F$101,6,FALSE),H4) -> 914.05 | J4: 0.25 | K4: =IF(J4="",1-(M4/(G4*I4)),J4) -> 0.25 | L4: Credit Card | M4: 2742.15 | N4: =IF(M4="",G4*I4*(1-K4),M4) -> 2742.15
A5: SALE3 | B5: 45259 | C5: CUST1346 | D5: PROD76 | E5: STORE8 | F5: 1 | G5: =IF(F5="",M5/(I5*(1-J5)),F5) -> 1 | H5: 921.51 | I5: =IF(H5="",VLOOKUP($D5,Product_Dim_Cleaned!$A$2:$F$101,6,FALSE),H5) -> 921.51 | J5: 0.16 | K5: =IF(J5="",1-(M5/(G5*I5)),J5) -> 0.16 | L5: COD | M5: 774.0684 | N5: =IF(M5="",G5*I5*(1-K5),M5) -> 774.0684
A6: SALE4 | B6: 45297 | C6: CUST1493 | D6: PROD59 | E6: STORE5 | F6: 3 | G6: =IF(F6="",M6/(I6*(1-J6)),F6) -> 3 | H6: 745.3 | I6: =IF(H6="",VLOOKUP($D6,Product_Dim_Cleaned!$A$2:$F$101,6,FALSE),H6) -> 745.3 | J6: 0.18 | K6: =IF(J6="",1-(M6/(G6*I6)),J6) -> 0.18 | L6: Credit Card | M6: 1833.438 | N6: =IF(M6="",G6*I6*(1-K6),M6) -> 1833.438
A7: SALE5 | B7: 45499 | C7: CUST1116 | D7: PROD15 | E7: STORE7 | F7: 3 | G7: =IF(F7="",M7/(I7*(1-J7)),F7) -> 3 | H7: 147.01 | I7: =IF(H7="",VLOOKUP($D7,Product_Dim_Cleaned!$A$2:$F$101,6,FALSE),H7) -> 147.01 | J7: 0.19 | K7: =IF(J7="",1-(M7/(G7*I7)),J7) -> 0.19 | L7: COD | M7: 357.2343 | N7: =IF(M7="",G7*I7*(1-K7),M7) -> 357.2343
A8: SALE6 | B8: 45850 | C8: CUST1016 | D8: PROD56 | E8: STORE4 | F8: 2 | G8: =IF(F8="",M8/(I8*(1-J8)),F8) -> 2 | H8: 785.31 | I8: =IF(H8="",VLOOKUP($D8,Product_Dim_Cleaned!$A$2:$F$101,6,FALSE),H8) -> 785.31 | J8: 0.15 | K8: =IF(J8="",1-(M8/(G8*I8)),J8) -> 0.15 | L8: PayPal | M8: 1335.027 | N8: =IF(M8="",G8*I8*(1-K8),M8) -> 1335.027
A9: SALE7 | B9: 45248 | C9: CUST1152 | D9: PROD70 | E9: STORE8 | F9: 4 | G9: =IF(F9="",M9/(I9*(1-J9)),F9) -> 4 | H9: 342.39 | I9: =IF(H9="",VLOOKUP($D9,Product_Dim_Cleaned!$A$2:$F$101,6,FALSE),H9) -> 342.39 | J9: 0.23 | K9: =IF(J9="",1-(M9/(G9*I9)),J9) -> 0.23 | L9: PayPal | M9: 1054.5612 | N9: =IF(M9="",G9*I9*(1-K9),M9) -> 1054.5612
A10: SALE8 | B10: 45781 | C10: CUST1187 | D10: PROD99 | E10: STORE5 | G10: =IF(F10="",M10/(I10*(1-J10)),F10) -> 3 | H10: 448.25 | I10: =IF(H10="",VLOOKUP($D10,Product_Dim_Cleaned!$A$2:$F$101,6,FALSE),H10) -> 448.25 | J10: 0.07 | K10: =IF(J10="",1-(M10/(G10*I10)),J10) -> 0.07 | L10: PayPal | M10: 1250.6175 | N10: =IF(M10="",G10*I10*(1-K10),M10) -> 1250.6175
A11: SALE9 | B11: 45869 | C11: CUST1464 | D11: PROD33 | E11: STORE0 | F11: 2 | G11: =IF(F11="",M11/(I11*(1-J11)),F11) -> 2 | H11: 873.17 | I11: =IF(H11="",VLOOKUP($D11,Product_Dim_Cleaned!$A$2:$F$101,6,FALSE),H11) -> 873.17 | J11: 0.23 | K11: =IF(J11="",1-(M11/(G11*I11)),J11) -> 0.23 | L11: PayPal | M11: 1344.6818 | N11: =IF(M11="",G11*I11*(1-K11),M11) -> 1344.6818
A12: SALE10 | B12: 45335 | C12: CUST1065 | D12: PROD24 | E12: STORE14 | F12: 1 | G12: =IF(F12="",M12/(I12*(1-J12)),F12) -> 1 | H12: 278.63 | I12: =IF(H12="",VLOOKUP($D12,Product_Dim_Cleaned!$A$2:$F$101,6,FALSE),H12) -> 278.63 | J12: 0.07 | K12: =IF(J12="",1-(M12/(G12*I12)),J12) -> 0.07 | L12: Credit Card | M12: 259.1259 | N12: =IF(M12="",G12*I12*(1-K12),M12) -> 259.1259
A13: SALE11 | B13: 45801 | C13: CUST1320 | D13: PROD39 | E13: STORE1 | F13: 4 | G13: =IF(F13="",M13/(I13*(1-J13)),F13) -> 4 | H13: 286.92 | I13: =IF(H13="",VLOOKUP($D13,Product_Dim_Cleaned!$A$2:$F$101,6,FALSE),H13) -> 286.92 | J13: 0.17 | K13: =IF(J13="",1-(M13/(G13*I13)),J13) -> 0.17 | L13: Credit Card | M13: 952.5744 | N13: =IF(M13="",G13*I13*(1-K13),M13) -> 952.5744
A14: SALE12 | B14: 45528 | C14: CUST1237 | D14: PROD88 | E14: STORE4 | F14: 4 | G14: =IF(F14="",M14/(I14*(1-J14)),F14) -> 4 | H14: 644.58 | I14: =IF(H14="",VLOOKUP($D14,Product_Dim_Cleaned!$A$2:$F$101,6,FALSE),H14) -> 644.58 | J14: 0.01 | K14: =IF(J14="",1-(M14/(G14*I14)),J14) -> 0.01 | L14: Credit Card | M14: 2552.5368 | N14: =IF(M14="",G14*I14*(1-K14),M14) -> 2552.5368
A15: SALE13 | B15: 45875 | C15: CUST1443 | D15: PROD34 | E15: STORE16 | F15: 2 | G15: =IF(F15="",M15/(I15*(1-J15)),F15) -> 2 | H15: 316.9 | I15: =IF(H15="",VLOOKUP($D15,Product_Dim_Cleaned!$A$2:$F$101,6,FALSE),H15) -> 316.9 | J15: 0.3 | K15: =IF(J15="",1-(M15/(G15*I15)),J15) -> 0.3 | L15: PayPal | M15: 443.66 | N15: =IF(M15="",G15*I15*(1-K15),M15) -> 443.66
A16: SALE14 | B16: 45829 | C16: CUST1348 | D16: PROD24 | E16: STORE15 | F16: 4 | G16: =IF(F16="",M16/(I16*(1-J16)),F16) -> 4 | H16: 403.47 | I16: =IF(H16="",VLOOKUP($D16,Product_Dim_Cleaned!$A$2:$F$101,6,FALSE),H16) -> 403.47 | J16: 0.29 | K16: =IF(J16="",1-(M16/(G16*I16)),J16) -> 0.29 | L16: PayPal | M16: 1145.8548 | N16: =IF(M16="",G16*I16*(1-K16),M16) -> 1145.8548
A17: SALE15 | B17: 45636 | C17: CUST1435 | D17: PROD36 | E17: STORE9 | G17: =IF(F17="",M17/(I17*(1-J17)),F17) -> 3 | H17: 871.34 | I17: =IF(H17="",VLOOKUP($D17,Product_Dim_Cleaned!$A$2:$F$101,6,FALSE),H17) -> 871.34 | J17: 0.04 | K17: =IF(J17="",1-(M17/(G17*I17)),J17) -> 0.04 | L17: COD | M17: 2509.4592 | N17: =IF(M17="",G17*I17*(1-K17),M17) -> 2509.4592
A18: SALE16 | B18: 45913 | C18: CUST1276 | D18: PROD65 | E18: STORE19 | F18: 2 | G18: =IF(F18="",M18/(I18*(1-J18)),F18) -> 2 | H18: 451.98 | I18: =IF(H18="",VLOOKUP($D18,Product_Dim_Cleaned!$A$2:$F$101,6,FALSE),H18) -> 451.98 | J18: 0.25 | K18: =IF(J18="",1-(M18/(G18*I18)),J18) -> 0.25 | L18: Credit Card | M18: 677.97 | N18: =IF(M18="",G18*I18*(1-K18),M18) -> 677.97
A19: SALE17 | B19: 45637 | C19: CUST1079 | D19: PROD27 | E19: STORE4 | F19: 2 | G19: =IF(F19="",M19/(I19*(1-J19)),F19) -> 2 | H19: 502.69 | I19: =IF(H19="",VLOOKUP($D19,Product_Dim_Cleaned!$A$2:$F$101,6,FALSE),H19) -> 502.69 | J19: 0.23 | K19: =IF(J19="",1-(M19/(G19*I19)),J19) -> 0.23 | L19: Credit Card | M19: 774.1426 | N19: =IF(M19="",G19*I19*(1-K19),M19) -> 774.1426
A20: SALE18 | B20: 45517 | C20: CUST1094 | D20: PROD39 | E20: STORE4 | F20: 2 | G20: =IF(F20="",M20/(I20*(1-J20)),F20) -> 2 | H20: 559.23 | I20: =IF(H20="",VLOOKUP($D20,Product_Dim_Cleaned!$A$2:$F$101,6,FALSE),H20) -> 559.23 | J20: 0.25 | K20: =IF(J20="",1-(M20/(G20*I20)),J20) -> 0.25 | L20: COD | M20: 838.845 | N20: =IF(M20="",G20*I20*(1-K20),M20) -> 838.845
A21: SALE19 | B21: 45369 | C21: CUST1239 | D21: PROD60 | E21: STORE13 | F21: 4 | G21: =IF(F21="",M21/(I21*(1-J21)),F21) -> 4 | I21: =IF(H21="",VLOOKUP($D21,Product_Dim_Cleaned!$A$2:$F$101,6,FALSE),H21) -> 482.75 | J21: 0.04 | K21: =IF(J21="",1-(M21/(G21*I21)),J21) -> 0.04 | L21: COD | M21: 1782.4512 | N21: =IF(M21="",G21*I21*(1-K21),M21) -> 1782.4512
A22: SALE20 | B22: 45843 | C22: CUST1144 | D22: PROD72 | E22: STORE17 | F22: 3 | G22: =IF(F22="",M22/(I22*(1-J22)),F22) -> 3 | H22: 986.04 | I22: =IF(H22="",VLOOKUP($D22,Product_Dim_Cleaned!$A$2:$F$101,6,FALSE),H22) -> 986.04 | J22: 0.27 | K22: =IF(J22="",1-(M22/(G22*I22)),J22) -> 0.27 | L22: COD | M22: 2159.4276 | N22: =IF(M22="",G22*I22*(1-K22),M22) -> 2159.4276
A23: SALE21 | B23: 45447 | C23: CUST1396 | D23: PROD43 | E23: STORE18 | F23: 1 | G23: =IF(F23="",M23/(I23*(1-J23)),F23) -> 1 | H23: 589.56 | I23: =IF(H23="",VLOOKUP($D23,Product_Dim_Cleaned!$A$2:$F$101,6,FALSE),H23) -> 589.56 | J23: 0.22 | K23: =IF(J23="",1-(M23/(G23*I23)),J23) -> 0.22 | L23: Credit Card | M23: 459.8568 | N23: =IF(M23="",G23*I23*(1-K23),M23) -> 459.8568
A24: SALE22 | B24: 45394 | C24: CUST1476 | D24: PROD69 | E24: STORE10 | F24: 3 | G24: =IF(F24="",M24/(I24*(1-J24)),F24) -> 3 | H24: 979.42 | I24: =IF(H24="",VLOOKUP($D24,Product_Dim_Cleaned!$A$2:$F$101,6,FALSE),H24) -> 979.42 | J24: 0.03 | K24: =IF(J24="",1-(M24/(G24*I24)),J24) -> 0.03 | L24: PayPal | M24: 2850.1122 | N24: =IF(M24="",G24*I24*(1-K24),M24) -> 2850.1122
A25: SALE23 | B25: 45466 | C25: CUST1368 | D25: PROD12 | E25: STORE8 | F25: 1 | G25: =IF(F25="",M25/(I25*(1-J25)),F25) -> 1 | H25: 719.28 | I25: =IF(H25="",VLOOKUP($D25,Product_Dim_Cleaned!$A$2:$F$101,6,FALSE),H25) -> 719.28 | J25: 0.08 | K25: =IF(J25="",1-(M25/(G25*I25)),J25) -> 0.08 | L25: Credit Card | M25: 661.7376 | N25: =IF(M25="",G25*I25*(1-K25),M25) -> 661.7376
A26: SALE24 | B26: 45908 | C26: CUST1186 | D26: PROD67 | E26: STORE6 | F26: 3 | G26: =IF(F26="",M26/(I26*(1-J26)),F26) -> 3 | H26: 77.6 | I26: =IF(H26="",VLOOKUP($D26,Product_Dim_Cleaned!$A$2:$F$101,6,FALSE),H26) -> 77.6 | J26: 0.07 | K26: =IF(J26="",1-(M26/(G26*I26)),J26) -> 0.07 | L26: Credit Card | M26: 216.504 | N26: =IF(M26="",G26*I26*(1-K26),M26) -> 216.504
A27: SALE25 | B27: 45552 | C27: CUST1381 | D27: PROD5 | E27: STORE3 | F27: 4 | G27: =IF(F27="",M27/(I27*(1-J27)),F27) -> 4 | H27: 852.71 | I27: =IF(H27="",VLOOKUP($D27,Product_Dim_Cleaned!$A$2:$F$101,6,FALSE),H27) -> 852.71 | J27: 0.14 | K27: =IF(J27="",1-(M27/(G27*I27)),J27) -> 0.14 | L27: PayPal | M27: 2933.3224 | N27: =IF(M27="",G27*I27*(1-K27),M27) -> 2933.3224
A28: SALE26 | B28: 45294 | C28: CUST1213 | D28: PROD98 | E28: STORE8 | F28: 4 | G28: =IF(F28="",M28/(I28*(1-J28)),F28) -> 4 | H28: 156.16 | I28: =IF(H28="",VLOOKUP($D28,Product_Dim_Cleaned!$A$2:$F$101,6,FALSE),H28) -> 156.16 | K28: =IF(J28="",1-(M28/(G28*I28)),J28) -> 0.04 | L28: Credit Card | M28: 599.6544 | N28: =IF(M28="",G28*I28*(1-K28),M28) -> 599.6544
A29: SALE27 | B29: 45710 | C29: CUST1200 | D29: PROD77 | E29: STORE8 | F29: 3 | G29: =IF(F29="",M29/(I29*(1-J29)),F29) -> 3 | H29: 815.49 | I29: =IF(H29="",VLOOKUP($D29,Product_Dim_Cleaned!$A$2:$F$101,6,FALSE),H29) -> 815.49 | J29: 0.17 | K29: =IF(J29="",1-(M29/(G29*I29)),J29) -> 0.17 | L29: Credit Card | M29: 2030.5701 | N29: =IF(M29="",G29*I29*(1-K29),M29) -> 2030.5701
A30: SALE28 | B30: 45923 | C30: CUST1148 | D30: PROD13 | E30: STORE2 | F30: 2 | G30: =IF(F30="",M30/(I30*(1-J30)),F30) -> 2 | H30: 74.21 | I30: =IF(H30="",VLOOKUP($D30,Product_Dim_Cleaned!$A$2:$F$101,6,FALSE),H30) -> 74.21 | J30: 0.11 | K30: =IF(J30="",1-(M30/(G30*I30)),J30) -> 0.11 | L30: PayPal | M30: 132.0938 | N30: =IF(M30="",G30*I30*(1-K30),M30) -> 132.0938
A31: SALE29 | B31: 45302 | C31: CUST1348 | D31: PROD99 | E31: STORE3 | G31: =IF(F31="",M31/(I31*(1-J31)),F31) -> 4 | H31: 451.67 | I31: =IF(H31="",VLOOKUP($D31,Product_Dim_Cleaned!$A$2:$F$101,6,FALSE),H31) -> 451.67 | J31: 0.15 | K31: =IF(J31="",1-(M31/(G31*I31)),J31) -> 0.15 | L31: Credit Card | M31: 1535.678 | N31: =IF(M31="",G31*I31*(1-K31),M31) -> 1535.678
A32: SALE30 | B32: 45217 | C32: CUST1028 | D32: PROD5 | E32: STORE19 | F32: 1 | G32: =IF(F32="",M32/(I32*(1-J32)),F32) -> 1 | H32: 429.38 | I32: =IF(H32="",VLOOKUP($D32,Product_Dim_Cleaned!$A$2:$F$101,6,FALSE),H32) -> 429.38 | J32: 0.13 | K32: =IF(J32="",1-(M32/(G32*I32)),J32) -> 0.13 | L32: PayPal | M32: 373.5606 | N32: =IF(M32="",G32*I32*(1-K32),M32) -> 373.5606
A33: SALE31 | B33: 45593 | C33: CUST1412 | D33: PROD53 | E33: STORE12 | F33: 2 | G33: =IF(F33="",M33/(I33*(1-J33)),F33) -> 2 | H33: 148.96 | I33: =IF(H33="",VLOOKUP($D33,Product_Dim_Cleaned!$A$2:$F$101,6,FALSE),H33) -> 148.96 | J33: 0.03 | K33: =IF(J33="",1-(M33/(G33*I33)),J33) -> 0.03 | L33: COD | M33: 288.9824 | N33: =IF(M33="",G33*I33*(1-K33),M33) -> 288.9824
A34: SALE32 | B34: 45597 | C34: CUST1398 | D34: PROD75 | E34: STORE8 | F34: 4 | G34: =IF(F34="",M34/(I34*(1-J34)),F34) -> 4 | H34: 313.83 | I34: =IF(H34="",VLOOKUP($D34,Product_Dim_Cleaned!$A$2:$F$101,6,FALSE),H34) -> 313.83 | J34: 0.08 | K34: =IF(J34="",1-(M34/(G34*I34)),J34) -> 0.08 | L34: Credit Card | M34: 1154.8944 | N34: =IF(M34="",G34*I34*(1-K34),M34) -> 1154.8944
A35: SALE33 | B35: 45620 | C35: CUST1453 | D35: PROD12 | E35: STORE6 | F35: 2 | G35: =IF(F35="",M35/(I35*(1-J35)),F35) -> 2 | H35: 717.31 | I35: =IF(H35="",VLOOKUP($D35,Product_Dim_Cleaned!$A$2:$F$101,6,FALSE),H35) -> 717.31 | J35: 0.15 | K35: =IF(J35="",1-(M35/(G35*I35)),J35) -> 0.15 | L35: Credit Card | M35: 1219.427 | N35: =IF(M35="",G35*I35*(1-K35),M35) -> 1219.427
A36: SALE34 | B36: 45215 | C36: CUST1344 | D36: PROD79 | E36: STORE1 | G36: =IF(F36="",M36/(I36*(1-J36)),F36) -> 3 | H36: 873.22 | I36: =IF(H36="",VLOOKUP($D36,Product_Dim_Cleaned!$A$2:$F$101,6,FALSE),H36) -> 873.22 | J36: 0.18 | K36: =IF(J36="",1-(M36/(G36*I36)),J36) -> 0.18 | L36: Credit Card | M36: 2148.1212 | N36: =IF(M36="",G36*I36*(1-K36),M36) -> 2148.1212
A37: SALE35 | B37: 45878 | C37: CUST1218 | D37: PROD16 | E37: STORE3 | F37: 4 | G37: =IF(F37="",M37/(I37*(1-J37)),F37) -> 4 | H37: 109.36 | I37: =IF(H37="",VLOOKUP($D37,Product_Dim_Cleaned!$A$2:$F$101,6,FALSE),H37) -> 109.36 | J37: 0.19 | K37: =IF(J37="",1-(M37/(G37*I37)),J37) -> 0.19 | L37: COD | M37: 354.3264 | N37: =IF(M37="",G37*I37*(1-K37),M37) -> 354.3264
A38: SALE36 | B38: 45635 | C38: CUST1086 | D38: PROD5 | E38: STORE7 | F38: 3 | G38: =IF(F38="",M38/(I38*(1-J38)),F38) -> 3 | H38: 559.52 | I38: =IF(H38="",VLOOKUP($D38,Product_Dim_Cleaned!$A$2:$F$101,6,FALSE),H38) -> 559.52 | J38: 0.16 | K38: =IF(J38="",1-(M38/(G38*I38)),J38) -> 0.16 | L38: PayPal | M38: 1409.9904 | N38: =IF(M38="",G38*I38*(1-K38),M38) -> 1409.9904
A39: SALE37 | B39: 45329 | C39: CUST1492 | D39: PROD10 | E39: STORE17 | F39: 3 | G39: =IF(F39="",M39/(I39*(1-J39)),F39) -> 3 | H39: 121.76 | I39: =IF(H39="",VLOOKUP($D39,Product_Dim_Cleaned!$A$2:$F$101,6,FALSE),H39) -> 121.76 | J39: 0.27 | K39: =IF(J39="",1-(M39/(G39*I39)),J39) -> 0.27 | L39: PayPal | M39: 266.6544 | N39: =IF(M39="",G39*I39*(1-K39),M39) -> 266.6544
A40: SALE38 | B40: 45378 | C40: CUST1189 | D40: PROD33 | E40: STORE13 | F40: 4 | G40: =IF(F40="",M40/(I40*(1-J40)),F40) -> 4 | H40: 735.32 | I40: =IF(H40="",VLOOKUP($D40,Product_Dim_Cleaned!$A$2:$F$101,6,FALSE),H40) -> 735.32 | J40: 0.06 | K40: =IF(J40="",1-(M40/(G40*I40)),J40) -> 0.06 | L40: COD | M40: 2764.8032 | N40: =IF(M40="",G40*I40*(1-K40),M40) -> 2764.8032
...

Sheet Sales_Fact_Cleaned
A1: Sales_ID | B1: Order_Date | C1: Customer_ID | D1: Product_ID | E1: Store_ID | F1: Quantity | G1: Unit_Price | H1: Discount | I1: Payment_Type | J1: Total_Amount | K1: Customer_Name | L1: Product_Name | M1: Store_Name
A2: SALE0 | B2: 45480 | C2: CUST1409 | D2: PROD97 | E2: STORE3 | F2: 1 | G2: 245.98 | H2: 0.09 | I2: Credit Card | J2: 198.4164 | K2: =VLOOKUP($C2,Customer_Dim_Cleaned!$A$2:$H$501,2,FALSE) -> Sarah Smith | L2: =VLOOKUP($D2,Product_Dim_Cleaned!$A$2:$F$101,2,FALSE) -> Cricket Bat | M2: =VLOOKUP($E2,Store_Dim_Cleaned!$A$2:$E$21,2,FALSE) -> Johnson-Wright
A3: SALE1 | B3: 45285 | C3: CUST1467 | D3: PROD74 | E3: STORE17 | F3: 3 | G3: 104.47 | H3: 0.27 | I3: PayPal | J3: 228.7893 | K3: =VLOOKUP($C3,Customer_Dim_Cleaned!$A$2:$H$501,2,FALSE) -> Michael Foley | L3: =VLOOKUP($D3,Product_Dim_Cleaned!$A$2:$F$101,2,FALSE) -> Bluetooth Car Audio System | M3: =VLOOKUP($E3,Store_Dim_Cleaned!$A$2:$E$21,2,FALSE) -> Holloway Ltd
A4: SALE2 | B4: 45446 | C4: CUST1056 | D4: PROD49 | E4: STORE8 | F4: 4 | G4: 914.05 | H4: 0.25 | I4: Credit Card | J4: 2742.15 | K4: =VLOOKUP($C4,Customer_Dim_Cleaned!$A$2:$H$501,2,FALSE) -> Christopher Sutton | L4: =VLOOKUP($D4,Product_Dim_Cleaned!$A$2:$F$101,2,FALSE) -> Men's Roll-On Perfume | M4: =VLOOKUP($E4,Store_Dim_Cleaned!$A$2:$E$21,2,FALSE) -> Bean, Jones and Park
A5: SALE3 | B5: 45259 | C5: CUST1346 | D5: PROD76 | E5: STORE8 | F5: 1 | G5: 921.51 | H5: 0.16 | I5: COD | J5: 774.0684 | K5: =VLOOKUP($C5,Customer_Dim_Cleaned!$A$2:$H$501,2,FALSE) -> John Jordan | L5: =VLOOKUP($D5,Product_Dim_Cleaned!$A$2:$F$101,2,FALSE) -> Wireless Mouse | M5: =VLOOKUP($E5,Store_Dim_Cleaned!$A$2:$E$21,2,FALSE) -> Bean, Jones and Park
A6: SALE4 | B6: 45297 | C6: CUST1493 | D6: PROD59 | E6: STORE5 | F6: 3 | G6: 745.3 | H6: 0.18 | I6: Credit Card | J6: 1833.438 | K6: =VLOOKUP($C6,Customer_Dim_Cleaned!$A$2:$H$501,2,FALSE) -> Amanda Powell | L6: =VLOOKUP($D6,Product_Dim_Cleaned!$A$2:$F$101,2,FALSE) -> Men's Hair Styling Gel | M6: =VLOOKUP($E6,Store_Dim_Cleaned!$A$2:$E$21,2,FALSE) -> Gray Ltd
A7: SALE5 | B7: 45499 | C7: CUST1116 | D7: PROD15 | E7: STORE7 | F7: 3 | G7: 147.01 | H7: 0.19 | I7: COD | J7: 357.2343 | K7: =VLOOKUP($C7,Customer_Dim_Cleaned!$A$2:$H$501,2,FALSE) -> Anthony Phillips | L7: =VLOOKUP($D7,Product_Dim_Cleaned!$A$2:$F$101,2,FALSE) -> 4K Home Projector | M7: =VLOOKUP($E7,Store_Dim_Cleaned!$A$2:$E$21,2,FALSE) -> Martinez-Mullins
A8: SALE6 | B8: 45850 | C8: CUST1016 | D8: PROD56 | E8: STORE4 | F8: 2 | G8: 785.31 | H8: 0.15 | I8: PayPal | J8: 1335.027 | K8: =VLOOKUP($C8,Customer_Dim_Cleaned!$A$2:$H$501,2,FALSE) -> John Scott | L8: =VLOOKUP($D8,Product_Dim_Cleaned!$A$2:$F$101,2,FALSE) -> Premium Blanket Throw | M8: =VLOOKUP($E8,Store_Dim_Cleaned!$A$2:$E$21,2,FALSE) -> Alexander Group
A9: SALE7 | B9: 45248 | C9: CUST1152 | D9: PROD70 | E9: STORE8 | F9: 4 | G9: 342.39 | H9: 0.23 | I9: PayPal | J9: 1054.5612 | K9: =VLOOKUP($C9,Customer_Dim_Cleaned!$A$2:$H$501,2,FALSE) -> Patrick Roberts | L9: =VLOOKUP($D9,Product_Dim_Cleaned!$A$2:$F$101,2,FALSE) -> Kitchen Storage Rack | M9: =VLOOKUP($E9,Store_Dim_Cleaned!$A$2:$E$21,2,FALSE) -> Bean, Jones and Park
A10: SALE8 | B10: 45781 | C10: CUST1187 | D10: PROD99 | E10: STORE5 | F10: 3 | G10: 448.25 | H10: 0.07 | I10: PayPal | J10: 1250.6175 | K10: =VLOOKUP($C10,Customer_Dim_Cleaned!$A$2:$H$501,2,FALSE) -> Dr. Suzanne Bullock | L10: =VLOOKUP($D10,Product_Dim_Cleaned!$A$2:$F$101,2,FALSE) -> Stainless Steel Cookware Set | M10: =VLOOKUP($E10,Store_Dim_Cleaned!$A$2:$E$21,2,FALSE) -> Gray Ltd
A11: SALE9 | B11: 45869 | C11: CUST1464 | D11: PROD33 | E11: STORE0 | F11: 2 | G11: 873.17 | H11: 0.23 | I11: PayPal | J11: 1344.6818 | K11: =VLOOKUP($C11,Customer_Dim_Cleaned!$A$2:$H$501,2,FALSE) -> David Pierce | L11: =VLOOKUP($D11,Product_Dim_Cleaned!$A$2:$F$101,2,FALSE) -> Modern Wall Clock | M11: =VLOOKUP($E11,Store_Dim_Cleaned!$A$2:$E$21,2,FALSE) -> Rivera-Warner
A12: SALE10 | B12: 45335 | C12: CUST1065 | D12: PROD24 | E12: STORE14 | F12: 1 | G12: 278.63 | H12: 0.07 | I12: Credit Card | J12: 259.1259 | K12: =VLOOKUP($C12,Customer_Dim_Cleaned!$A$2:$H$501,2,FALSE) -> Michael Thomas | L12: =VLOOKUP($D12,Product_Dim_Cleaned!$A$2:$F$101,2,FALSE) -> Foldable Camping Chair | M12: =VLOOKUP($E12,Store_Dim_Cleaned!$A$2:$E$21,2,FALSE) -> Mcdonald Inc
A13: SALE11 | B13: 45801 | C13: CUST1320 | D13: PROD39 | E13: STORE1 | F13: 4 | G13: 286.92 | H13: 0.17 | I13: Credit Card | J13: 952.5744 | K13: =VLOOKUP($C13,Customer_Dim_Cleaned!$A$2:$H$501,2,FALSE) -> Jessica Gonzalez | L13: =VLOOKUP($D13,Product_Dim_Cleaned!$A$2:$F$101,2,FALSE) -> Portable Power Bank | M13: =VLOOKUP($E13,Store_Dim_Cleaned!$A$2:$E$21,2,FALSE) -> Martinez, Adkins and Johnson
... A2001: SALE1999 | B2001: 45267 | C2001: CUST1023 | D2001: PROD76 | E2001: STORE19 | F2001: 3 | G2001: 68.45 | H2001: 0.17 | I2001: PayPal | J2001: 170.4405 | K2001: =VLOOKUP($C2001,Customer_Dim_Cleaned!$A$2:$H$501,2,FALSE) -> Jonathan Steele | L2001: =VLOOKUP($D2001,Product_Dim_Cleaned!$A$2:$F$101,2,FALSE) -> Wireless Mouse | M2001: =VLOOKUP($E2001,Store_Dim_Cleaned!$A$2:$E$21,2,FALSE) -> Mann-Austin

Sheet Pivot Table
A1: Month | B1: Sum of Total_Amount | C1: Sum of Quantity | E1: Store Type | F1: Sum of Total_Amount | H1: Loyalty Level | I1: Sum of Total_Amount
A2: Jan | B2: 174449.14 | C2: 398 | E2: Flagship | F2: 848576.67 | H2: Bronze | I2: 522623.38
